<sdf version='1.6'>
  <world name='default'>
    <light name='sun' type='directional'>
      <cast_shadows>1</cast_shadows>
      <pose frame=''>0 0 10 0 -0 0</pose>
      <diffuse>0.8 0.8 0.8 1</diffuse>
      <specular>0.1 0.1 0.1 1</specular>
      <attenuation>
        <range>1000</range>
        <constant>0.9</constant>
        <linear>0.01</linear>
        <quadratic>0.001</quadratic>
      </attenuation>
      <direction>-0.5 0.5 -1</direction>
    </light>
    <model name='ground_plane'>
      <static>1</static>
      <link name='link'>
        <collision name='collision'>
          <geometry>
            <plane>
              <normal>0 0 1</normal>
              <size>100 100</size>
            </plane>
          </geometry>
          <surface>
            <friction>
              <ode>
                <mu>100</mu>
                <mu2>50</mu2>
              </ode>
              <torsional>
                <ode/>
              </torsional>
            </friction>
            <contact>
              <ode/>
            </contact>
            <bounce/>
          </surface>
          <max_contacts>10</max_contacts>
        </collision>
        <visual name='visual'>
          <cast_shadows>0</cast_shadows>
          <geometry>
            <plane>
              <normal>0 0 1</normal>
              <size>100 100</size>
            </plane>
          </geometry>
          <material>
            <script>
              <uri>file://media/materials/scripts/gazebo.material</uri>
              <name>Gazebo/Grey</name>
            </script>
          </material>
        </visual>
        <self_collide>0</self_collide>
        <kinematic>0</kinematic>
        <gravity>1</gravity>
      </link>
    </model>
    <gravity>0 0 -9.8</gravity>
    <magnetic_field>6e-06 2.3e-05 -4.2e-05</magnetic_field>
    <atmosphere type='adiabatic'/>
    <physics name='default_physics' default='0' type='ode'>
      <max_step_size>0.001</max_step_size>
      <real_time_factor>1</real_time_factor>
      <real_time_update_rate>1000</real_time_update_rate>
    </physics>
    <scene>
      <ambient>0.4 0.4 0.4 1</ambient>
      <background>0.7 0.7 0.7 1</background>
      <shadows>1</shadows>
    </scene>
    <spherical_coordinates>
      <surface_model>EARTH_WGS84</surface_model>
      <latitude_deg>0</latitude_deg>
      <longitude_deg>0</longitude_deg>
      <elevation>0</elevation>
      <heading_deg>0</heading_deg>
    </spherical_coordinates>
    <model name='asc'>
      <link name='base_link'>
        <pose frame=''>0 0 0 0 -0 0</pose>
        <inertial>
          <pose frame=''>-0.18729 0.001448 -0.133425 0 -0 0</pose>
          <mass>55.5245</mass>
          <inertia>
            <ixx>1.24828</ixx>
            <ixy>0.000308394</ixy>
            <ixz>-0.317313</ixz>
            <iyy>2.36635</iyy>
            <iyz>0.00086408</iyz>
            <izz>1.85995</izz>
          </inertia>
        </inertial>
        <collision name='base_link_fixed_joint_lump__velodyne_base_link_collision'>
          <pose frame=''>0.063 0 0.56585 0 -0 0</pose>
          <geometry>
            <cylinder>
              <length>0.0717</length>
              <radius>0.0516</radius>
            </cylinder>
          </geometry>
          <max_contacts>10</max_contacts>
          <surface>
            <contact>
              <ode/>
            </contact>
            <bounce/>
            <friction>
              <torsional>
                <ode/>
              </torsional>
              <ode/>
            </friction>
          </surface>
        </collision>
        <visual name='base_link_fixed_joint_lump__frame_link_visual'>
          <pose frame=''>0 0 0 0 -0 0</pose>
          <geometry>
            <mesh>
              <scale>1 1 1</scale>
              <uri>/home/abbe/catkin_ws/src/asc_project/asc_description/meshes/base_link.STL</uri>
            </mesh>
          </geometry>
        </visual>
        <visual name='base_link_fixed_joint_lump__zed_camera_center_visual_1'>
          <pose frame=''>0.149 0 0.49 0 -0 0</pose>
          <geometry>
            <mesh>
              <scale>1 1 1</scale>
              <uri>/home/abbe/catkin_ws/src/asc_project/asc_description/meshes/ZED/ZED.stl</uri>
            </mesh>
          </geometry>
          <material>
            <script>
              <uri>__default__</uri>
              <name>__default__</name>
            </script>
          </material>
        </visual>
        <visual name='base_link_fixed_joint_lump__velodyne_base_link_visual_2'>
          <pose frame=''>0.063 0 0.53 0 -0 0</pose>
          <geometry>
            <mesh>
              <scale>1 1 1</scale>
              <uri>/opt/ros/kinetic/share/velodyne_description/meshes/VLP16_base_1.dae</uri>
            </mesh>
          </geometry>
        </visual>
        <visual name='base_link_fixed_joint_lump__velodyne_base_link_visual_3'>
          <pose frame=''>0.063 0 0.53 0 -0 0</pose>
          <geometry>
            <mesh>
              <scale>1 1 1</scale>
              <uri>/opt/ros/kinetic/share/velodyne_description/meshes/VLP16_base_2.dae</uri>
            </mesh>
          </geometry>
        </visual>
        <visual name='base_link_fixed_joint_lump__velodyne_visual_4'>
          <pose frame=''>0.063 0 0.53 0 -0 0</pose>
          <geometry>
            <mesh>
              <scale>1 1 1</scale>
              <uri>/opt/ros/kinetic/share/velodyne_description/meshes/VLP16_scan.dae</uri>
            </mesh>
          </geometry>
          <material>
            <script>
              <uri>__default__</uri>
              <name>__default__</name>
            </script>
          </material>
        </visual>
        <velocity_decay/>
        <sensor name='openni_camera_camera' type='depth'>
          <always_on>1</always_on>
          <visualize>1</visualize>
          <camera name='__default__'>
            <horizontal_fov>1.39626</horizontal_fov>
            <image>
              <width>640</width>
              <height>480</height>
              <format>R8G8B8</format>
            </image>
            <clip>
              <near>0.1</near>
              <far>25</far>
            </clip>
          </camera>
          <plugin name='camera_plugin' filename='libgazebo_ros_openni_kinect.so'>
            <baseline>0.2</baseline>
            <alwaysOn>true</alwaysOn>
            <updateRate>0.0</updateRate>
            <cameraName>camera_ir</cameraName>
            <imageTopicName>/zed/zed_node/rgb/image_rect_color</imageTopicName>
            <cameraInfoTopicName>/zed/zed_node/rgb/camera_info</cameraInfoTopicName>
            <depthImageTopicName>/zed/zed_node/depth/depth_registered</depthImageTopicName>
            <depthImageCameraInfoTopicName>/zed/zed_node/depth/image_raw/camera_info</depthImageCameraInfoTopicName>
            <pointCloudTopicName>/zed/zed_node/point_cloud/cloud_registered</pointCloudTopicName>
            <frameName>camera_link_pc</frameName>
            <pointCloudCutoff>0.4</pointCloudCutoff>
            <distortionK1>0</distortionK1>
            <distortionK2>0</distortionK2>
            <distortionK3>0</distortionK3>
            <distortionT1>0</distortionT1>
            <distortionT2>0</distortionT2>
            <CxPrime>0</CxPrime>
            <Cx>0</Cx>
            <Cy>0</Cy>
            <focalLength>0</focalLength>
            <hackBaseline>0</hackBaseline>
            <robotNamespace>/</robotNamespace>
          </plugin>
          <pose frame=''>0.149 0 0.49 0 -0 0</pose>
        </sensor>
        <gravity>1</gravity>
        <velocity_decay/>
        <self_collide>0</self_collide>
        <sensor name='velodyne-VLP16' type='ray'>
          <visualize>0</visualize>
          <update_rate>10</update_rate>
          <ray>
            <scan>
              <horizontal>
                <samples>440</samples>
                <resolution>1</resolution>
                <min_angle>-3.14159</min_angle>
                <max_angle>3.14159</max_angle>
              </horizontal>
              <vertical>
                <samples>16</samples>
                <resolution>1</resolution>
                <min_angle>-0.261799</min_angle>
                <max_angle>0.261799</max_angle>
              </vertical>
            </scan>
            <range>
              <min>0.3</min>
              <max>131</max>
              <resolution>0.001</resolution>
            </range>
            <noise>
              <type>gaussian</type>
              <mean>0</mean>
              <stddev>0</stddev>
            </noise>
          </ray>
          <plugin name='gazebo_ros_laser_controller' filename='libgazebo_ros_velodyne_laser.so'>
            <topicName>/os1_cloud_node/points</topicName>
            <frameName>velodyne</frameName>
            <min_range>0.9</min_range>
            <max_range>130.0</max_range>
            <gaussianNoise>0.008</gaussianNoise>
            <robotNamespace>/</robotNamespace>
          </plugin>
          <pose frame=''>0.063 0 0.5677 0 -0 0</pose>
        </sensor>
        <kinematic>0</kinematic>
      </link>
      <link name='front_left_steering_link'>
        <pose frame=''>0.35635 0.22966 0.274 0.28907 0.000242 -1.5707</pose>
        <inertial>
          <pose frame=''>0 0 0 0 -0 0</pose>
          <mass>5.71439</mass>
          <inertia>
            <ixx>0.00107634</ixx>
            <ixy>1.51574e-05</ixy>
            <ixz>-6.94838e-05</ixz>
            <iyy>0.000914613</iyy>
            <iyz>0.000195407</iyz>
            <izz>0.000234022</izz>
          </inertia>
        </inertial>
        <visual name='front_left_steering_link_visual'>
          <pose frame=''>0 0 0 0 -0 0</pose>
          <geometry>
            <mesh>
              <scale>1 1 1</scale>
              <uri>/home/abbe/catkin_ws/src/asc_project/asc_description/meshes/front_left_steering_link.STL</uri>
            </mesh>
          </geometry>
        </visual>
        <self_collide>0</self_collide>
        <kinematic>0</kinematic>
        <gravity>1</gravity>
      </link>
      <joint name='front_left_steering_joint' type='revolute'>
        <child>front_left_steering_link</child>
        <parent>base_link</parent>
        <axis>
          <xyz>-0.285061 -0.00026 0.958509</xyz>
          <limit>
            <lower>-0.8</lower>
            <upper>0.9</upper>
            <effort>100</effort>
            <velocity>100</velocity>
          </limit>
          <dynamics>
            <spring_reference>0</spring_reference>
            <spring_stiffness>0</spring_stiffness>
          </dynamics>
          <use_parent_model_frame>1</use_parent_model_frame>
        </axis>
      </joint>
      <link name='front_left_wheel_link'>
        <pose frame=''>0.430086 0.279707 0.108662 0.000286 -0 4e-06</pose>
        <inertial>
          <pose frame=''>-0 0 0.0051 0 -0 0</pose>
          <mass>3.69055</mass>
          <inertia>
            <ixx>0.117114</ixx>
            <ixy>1.38778e-17</ixy>
            <ixz>2.3755e-18</ixz>
            <iyy>0.117114</iyy>
            <iyz>3.40771e-17</iyz>
            <izz>0.227951</izz>
          </inertia>
        </inertial>
        <collision name='front_left_wheel_link_collision'>
          <pose frame=''>0 0 0 1.57 -0 0</pose>
          <geometry>
            <cylinder>
              <length>0.032</length>
              <radius>0.1</radius>
            </cylinder>
          </geometry>
          <max_contacts>10</max_contacts>
          <surface>
            <contact>
              <ode/>
            </contact>
            <bounce/>
            <friction>
              <torsional>
                <ode/>
              </torsional>
              <ode/>
            </friction>
          </surface>
        </collision>
        <visual name='front_left_wheel_link_visual'>
          <pose frame=''>0 0 0 1.57 -0 0</pose>
          <geometry>
            <cylinder>
              <length>0.032</length>
              <radius>0.1</radius>
            </cylinder>
          </geometry>
        </visual>
        <self_collide>0</self_collide>
        <kinematic>0</kinematic>
        <gravity>1</gravity>
      </link>
      <joint name='front_left_wheel_joint' type='revolute'>
        <child>front_left_wheel_link</child>
        <parent>front_left_steering_link</parent>
        <axis>
          <xyz>5.8e-05 -1 0.000274</xyz>
          <limit>
            <lower>-1e+16</lower>
            <upper>1e+16</upper>
          </limit>
          <dynamics>
            <spring_reference>0</spring_reference>
            <spring_stiffness>0</spring_stiffness>
          </dynamics>
          <use_parent_model_frame>1</use_parent_model_frame>
        </axis>
      </joint>
      <link name='front_right_steering_link'>
        <pose frame=''>0.35635 -0.23074 0.27672 0.29046 -0.12882 -1.6092</pose>
        <inertial>
          <pose frame=''>0 0 0 0 -0 0</pose>
          <mass>5.71439</mass>
          <inertia>
            <ixx>0.00107634</ixx>
            <ixy>1.51574e-05</ixy>
            <ixz>-6.94838e-05</ixz>
            <iyy>0.000914613</iyy>
            <iyz>0.000195407</iyz>
            <izz>0.000234022</izz>
          </inertia>
        </inertial>
        <visual name='front_right_steering_link_visual'>
          <pose frame=''>0 0 0 0 -0 0</pose>
          <geometry>
            <mesh>
              <scale>1 1 1</scale>
              <uri>/home/abbe/catkin_ws/src/asc_project/asc_description/meshes/front_right_steering_link.STL</uri>
            </mesh>
          </geometry>
        </visual>
        <self_collide>0</self_collide>
        <kinematic>0</kinematic>
        <gravity>1</gravity>
      </link>
      <joint name='front_right_steering_joint' type='revolute'>
        <child>front_right_steering_link</child>
        <parent>base_link</parent>
        <axis>
          <xyz>-0.281456 0.133988 0.950173</xyz>
          <limit>
            <lower>-0.8</lower>
            <upper>0.9</upper>
            <effort>100</effort>
            <velocity>100</velocity>
          </limit>
          <dynamics>
            <spring_reference>0</spring_reference>
            <spring_stiffness>0</spring_stiffness>
          </dynamics>
          <use_parent_model_frame>1</use_parent_model_frame>
        </axis>
      </joint>
      <link name='front_right_wheel_link'>
        <pose frame=''>0.430843 -0.279585 0.108826 -0.000284 -0 1.3e-05</pose>
        <inertial>
          <pose frame=''>-0 0 0.0051 0 -0 0</pose>
          <mass>3.69055</mass>
          <inertia>
            <ixx>0.117114</ixx>
            <ixy>1.38778e-17</ixy>
            <ixz>2.3755e-18</ixz>
            <iyy>0.117114</iyy>
            <iyz>3.40771e-17</iyz>
            <izz>0.227951</izz>
          </inertia>
        </inertial>
        <collision name='front_right_wheel_link_collision'>
          <pose frame=''>0 0 0 1.57 -0 0</pose>
          <geometry>
            <cylinder>
              <length>0.032</length>
              <radius>0.1</radius>
            </cylinder>
          </geometry>
          <max_contacts>10</max_contacts>
          <surface>
            <contact>
              <ode/>
            </contact>
            <bounce/>
            <friction>
              <torsional>
                <ode/>
              </torsional>
              <ode/>
            </friction>
          </surface>
        </collision>
        <visual name='front_right_wheel_link_visual'>
          <pose frame=''>0 0 0 1.57 -0 0</pose>
          <geometry>
            <cylinder>
              <length>0.032</length>
              <radius>0.1</radius>
            </cylinder>
          </geometry>
        </visual>
        <self_collide>0</self_collide>
        <kinematic>0</kinematic>
        <gravity>1</gravity>
      </link>
      <joint name='front_right_wheel_joint' type='revolute'>
        <child>front_right_wheel_link</child>
        <parent>front_right_steering_link</parent>
        <axis>
          <xyz>4.1e-05 1 0.000275</xyz>
          <limit>
            <lower>-1e+16</lower>
            <upper>1e+16</upper>
          </limit>
          <dynamics>
            <spring_reference>0</spring_reference>
            <spring_stiffness>0</spring_stiffness>
          </dynamics>
          <use_parent_model_frame>1</use_parent_model_frame>
        </axis>
      </joint>
      <link name='rear_left_steering_link'>
        <pose frame=''>-0.48012 0.29752 0.27 0 -0 0</pose>
        <inertial>
          <pose frame=''>0 0 0 0 -0 0</pose>
          <mass>5.71439</mass>
          <inertia>
            <ixx>0.00107634</ixx>
            <ixy>1.51574e-05</ixy>
            <ixz>-6.94838e-05</ixz>
            <iyy>0.000914613</iyy>
            <iyz>0.000195407</iyz>
            <izz>0.000234022</izz>
          </inertia>
        </inertial>
        <self_collide>0</self_collide>
        <kinematic>0</kinematic>
        <gravity>1</gravity>
      </link>
      <joint name='rear_left_steering_joint' type='revolute'>
        <child>rear_left_steering_link</child>
        <parent>base_link</parent>
        <axis>
          <xyz>0 0 1</xyz>
          <limit>
            <lower>0</lower>
            <upper>0</upper>
            <effort>0</effort>
            <velocity>0</velocity>
          </limit>
          <dynamics>
            <spring_reference>0</spring_reference>
            <spring_stiffness>0</spring_stiffness>
          </dynamics>
          <use_parent_model_frame>1</use_parent_model_frame>
        </axis>
      </joint>
      <link name='rear_left_wheel_link'>
        <pose frame=''>-0.48012 0.29752 0.11 0 -0 0</pose>
        <inertial>
          <pose frame=''>-0 0 0.0051 0 -0 0</pose>
          <mass>3.69055</mass>
          <inertia>
            <ixx>0.117114</ixx>
            <ixy>1.38778e-17</ixy>
            <ixz>2.3755e-18</ixz>
            <iyy>0.117114</iyy>
            <iyz>3.40771e-17</iyz>
            <izz>0.227951</izz>
          </inertia>
        </inertial>
        <collision name='rear_left_wheel_link_collision'>
          <pose frame=''>0 0 0 1.57 -0 0</pose>
          <geometry>
            <cylinder>
              <length>0.032</length>
              <radius>0.1</radius>
            </cylinder>
          </geometry>
          <max_contacts>10</max_contacts>
          <surface>
            <contact>
              <ode/>
            </contact>
            <bounce/>
            <friction>
              <torsional>
                <ode/>
              </torsional>
              <ode/>
            </friction>
          </surface>
        </collision>
        <visual name='rear_left_wheel_link_visual'>
          <pose frame=''>0 0 0 1.57 -0 0</pose>
          <geometry>
            <cylinder>
              <length>0.032</length>
              <radius>0.1</radius>
            </cylinder>
          </geometry>
        </visual>
        <self_collide>0</self_collide>
        <kinematic>0</kinematic>
        <gravity>1</gravity>
      </link>
      <joint name='rear_left_wheel_joint' type='revolute'>
        <child>rear_left_wheel_link</child>
        <parent>rear_left_steering_link</parent>
        <axis>
          <xyz>0 1 0</xyz>
          <limit>
            <lower>-1e+16</lower>
            <upper>1e+16</upper>
          </limit>
          <dynamics>
            <spring_reference>0</spring_reference>
            <spring_stiffness>0</spring_stiffness>
          </dynamics>
          <use_parent_model_frame>1</use_parent_model_frame>
        </axis>
      </joint>
      <link name='rear_right_steering_link'>
        <pose frame=''>-0.48012 -0.29752 0.27 0 -0 0</pose>
        <inertial>
          <pose frame=''>0 0 0 0 -0 0</pose>
          <mass>5.71439</mass>
          <inertia>
            <ixx>0.00107634</ixx>
            <ixy>1.51574e-05</ixy>
            <ixz>-6.94838e-05</ixz>
            <iyy>0.000914613</iyy>
            <iyz>0.000195407</iyz>
            <izz>0.000234022</izz>
          </inertia>
        </inertial>
        <self_collide>0</self_collide>
        <kinematic>0</kinematic>
        <gravity>1</gravity>
      </link>
      <joint name='rear_right_steering_joint' type='revolute'>
        <child>rear_right_steering_link</child>
        <parent>base_link</parent>
        <axis>
          <xyz>0 0 1</xyz>
          <limit>
            <lower>0</lower>
            <upper>0</upper>
            <effort>0</effort>
            <velocity>0</velocity>
          </limit>
          <dynamics>
            <spring_reference>0</spring_reference>
            <spring_stiffness>0</spring_stiffness>
          </dynamics>
          <use_parent_model_frame>1</use_parent_model_frame>
        </axis>
      </joint>
      <link name='rear_right_wheel_link'>
        <pose frame=''>-0.48012 -0.29752 0.11 0 -0 0</pose>
        <inertial>
          <pose frame=''>-0 0 0.0051 0 -0 0</pose>
          <mass>3.69055</mass>
          <inertia>
            <ixx>0.117114</ixx>
            <ixy>1.38778e-17</ixy>
            <ixz>2.3755e-18</ixz>
            <iyy>0.117114</iyy>
            <iyz>3.40771e-17</iyz>
            <izz>0.227951</izz>
          </inertia>
        </inertial>
        <collision name='rear_right_wheel_link_collision'>
          <pose frame=''>0 0 0 1.57 -0 0</pose>
          <geometry>
            <cylinder>
              <length>0.032</length>
              <radius>0.1</radius>
            </cylinder>
          </geometry>
          <max_contacts>10</max_contacts>
          <surface>
            <contact>
              <ode/>
            </contact>
            <bounce/>
            <friction>
              <torsional>
                <ode/>
              </torsional>
              <ode/>
            </friction>
          </surface>
        </collision>
        <visual name='rear_right_wheel_link_visual'>
          <pose frame=''>0 0 0 1.57 -0 0</pose>
          <geometry>
            <cylinder>
              <length>0.032</length>
              <radius>0.1</radius>
            </cylinder>
          </geometry>
        </visual>
        <self_collide>0</self_collide>
        <kinematic>0</kinematic>
        <gravity>1</gravity>
      </link>
      <joint name='rear_right_wheel_joint' type='revolute'>
        <child>rear_right_wheel_link</child>
        <parent>rear_right_steering_link</parent>
        <axis>
          <xyz>0 1 0</xyz>
          <limit>
            <lower>-1e+16</lower>
            <upper>1e+16</upper>
          </limit>
          <dynamics>
            <spring_reference>0</spring_reference>
            <spring_stiffness>0</spring_stiffness>
          </dynamics>
          <use_parent_model_frame>1</use_parent_model_frame>
        </axis>
      </joint>
      <plugin name='gazebo_ros_control' filename='libgazebo_ros_control.so'>
        <robotNamespace>/</robotNamespace>
        <robotSimType>gazebo_ros_control/DefaultRobotHWSim</robotSimType>
        <legacyModeNS>false</legacyModeNS>
      </plugin>
      <static>0</static>
      <plugin name='imu_controller' filename='libhector_gazebo_ros_imu.so'>
        <robotNamespace>/</robotNamespace>
        <updateRate>50.0</updateRate>
        <topicName>imu/data</topicName>
        <accelDrift>0.005 0.005 0.005</accelDrift>
        <accelGaussianNoise>0.005 0.005 0.005</accelGaussianNoise>
        <rateDrift>0.005 0.005 0.005</rateDrift>
        <rateGaussianNoise>0.005 0.005 0.005</rateGaussianNoise>
        <headingDrift>0.005</headingDrift>
        <headingGaussianNoise>0.005</headingGaussianNoise>
        <bodyName>base_link</bodyName>
        <xyzOffset>-0.063 0 -0.5677</xyzOffset>
        <rpyOffset>0 -0 0</rpyOffset>
      </plugin>
      <plugin name='gps_controller' filename='libhector_gazebo_ros_gps.so'>
        <robotNamespace>/</robotNamespace>
        <updateRate>40</updateRate>
        <bodyName>base_link</bodyName>
        <frameId>base_link</frameId>
        <topicName>navsat/fix</topicName>
        <velocityTopicName>navsat/vel</velocityTopicName>
        <drift>0.0001 0.0001 0.0001</drift>
      </plugin>
      <pose frame=''>0 0 0 0 -0 0</pose>
    </model>
    <model name='Wall'>
      <link name='link_0'>
        <pose frame=''>-0 -4e-06 -3e-06 0 -0 0</pose>
        <inertial>
          <mass>51.3684</mass>
          <inertia>
            <ixx>35.9696</ixx>
            <ixy>0</ixy>
            <ixz>0</ixz>
            <iyy>1557.56</iyy>
            <iyz>0</iyz>
            <izz>1530.15</izz>
          </inertia>
          <pose frame=''>0 0 0 0 -0 0</pose>
        </inertial>
        <visual name='visual'>
          <pose frame=''>0 0 0 0 -0 0</pose>
          <geometry>
            <box>
              <size>18.8799 1 2.72079</size>
            </box>
          </geometry>
          <material>
            <lighting>1</lighting>
            <script>
              <uri>file://media/materials/scripts/gazebo.material</uri>
              <name>Gazebo/Grey</name>
            </script>
            <ambient>0.3 0.3 0.3 1</ambient>
            <diffuse>0.7 0.7 0.7 1</diffuse>
            <specular>0.01 0.01 0.01 1</specular>
            <emissive>0 0 0 1</emissive>
          </material>
          <cast_shadows>1</cast_shadows>
          <transparency>0</transparency>
        </visual>
        <collision name='collision'>
          <laser_retro>0</laser_retro>
          <max_contacts>10</max_contacts>
          <pose frame=''>0 0 0 0 -0 0</pose>
          <geometry>
            <box>
              <size>18.8799 1 2.72079</size>
            </box>
          </geometry>
          <surface>
            <friction>
              <ode>
                <mu>1</mu>
                <mu2>1</mu2>
                <fdir1>0 0 0</fdir1>
                <slip1>0</slip1>
                <slip2>0</slip2>
              </ode>
              <torsional>
                <coefficient>1</coefficient>
                <patch_radius>0</patch_radius>
                <surface_radius>0</surface_radius>
                <use_patch_radius>1</use_patch_radius>
                <ode>
                  <slip>0</slip>
                </ode>
              </torsional>
            </friction>
            <bounce>
              <restitution_coefficient>0</restitution_coefficient>
              <threshold>1e+06</threshold>
            </bounce>
            <contact>
              <collide_without_contact>0</collide_without_contact>
              <collide_without_contact_bitmask>1</collide_without_contact_bitmask>
              <collide_bitmask>1</collide_bitmask>
              <ode>
                <soft_cfm>0</soft_cfm>
                <soft_erp>0.2</soft_erp>
                <kp>1e+13</kp>
                <kd>1</kd>
                <max_vel>0.01</max_vel>
                <min_depth>0</min_depth>
              </ode>
              <bullet>
                <split_impulse>1</split_impulse>
                <split_impulse_penetration_threshold>-0.01</split_impulse_penetration_threshold>
                <soft_cfm>0</soft_cfm>
                <soft_erp>0.2</soft_erp>
                <kp>1e+13</kp>
                <kd>1</kd>
              </bullet>
            </contact>
          </surface>
        </collision>
        <self_collide>0</self_collide>
        <kinematic>0</kinematic>
        <gravity>1</gravity>
      </link>
      <static>1</static>
      <allow_auto_disable>1</allow_auto_disable>
      <pose frame=''>-0.522523 -11.1241 0 0 -0 0</pose>
    </model>
    <state world_name='default'>
      <sim_time>40 703000000</sim_time>
      <real_time>144 245973526</real_time>
      <wall_time>1574841780 615803039</wall_time>
      <iterations>40703</iterations>
      <model name='Wall'>
        <pose frame=''>-0.522523 -11.1241 0 0 -0 0</pose>
        <scale>1 1 1</scale>
        <link name='link_0'>
          <pose frame=''>-0.522523 -11.1241 -3e-06 0 -0 0</pose>
          <velocity>0 0 0 0 -0 0</velocity>
          <acceleration>0 0 0 0 -0 0</acceleration>
          <wrench>0 0 0 0 -0 0</wrench>
        </link>
      </model>
      <model name='asc'>
        <pose frame=''>-0.006029 -0.028964 -0.009405 -8e-06 -0.001224 0.082492</pose>
        <scale>1 1 1</scale>
        <link name='base_link'>
          <pose frame=''>-0.006029 -0.028964 -0.009405 -8e-06 -0.001224 0.082492</pose>
          <velocity>-0.000808 -0.000829 0.000213 -0.011803 -0.001897 0.000388</velocity>
          <acceleration>1.25816 -3.00264 1.18893 -1.8593 1.14957 2.40339</acceleration>
          <wrench>69.8586 -166.72 66.0149 0 -0 0</wrench>
        </link>
        <link name='front_left_steering_link'>
          <pose frame=''>0.329852 0.229252 0.26503 0.290553 0.005584 -1.50602</pose>
          <velocity>-0.001298 0.002615 -0.002014 -0.040594 -0.110188 0.004584</velocity>
          <acceleration>-1.76472 5.9627 -0.214643 -2.96683 -0.081779 2.75719</acceleration>
          <wrench>-10.0843 34.0732 -1.22655 0 -0 0</wrench>
        </link>
        <link name='front_left_wheel_link'>
          <pose frame=''>0.400322 0.284829 0.10008 0.006286 -0.406527 0.062387</pose>
          <velocity>-0.001641 -0.000896 0.010303 0.008949 -0.015765 0.004078</velocity>
          <acceleration>-0.638654 -2.03559 23.1941 1.54319 -0.974324 1.01598</acceleration>
          <wrench>-2.35698 -7.51245 85.5991 0 -0 0</wrench>
        </link>
        <link name='front_right_steering_link'>
          <pose frame=''>0.367785 -0.229583 0.267753 0.292785 -0.128029 -1.53003</pose>
          <velocity>-0.001133 0.002684 0.00327 0.01204 -0.050256 0.013266</velocity>
          <acceleration>-3.29577 5.94024 12.0265 2.45321 0.800315 2.37413</acceleration>
          <wrench>-18.8333 33.9448 68.724 0 -0 0</wrench>
        </link>
        <link name='front_right_wheel_link'>
          <pose frame=''>0.446151 -0.272179 0.100007 0.000347 -0.412914 0.079098</pose>
          <velocity>-0.000854 -0.000181 0.009959 0.001807 -0.008595 0.001865</velocity>
          <acceleration>-2.36307 0.191761 37.2408 1.80582 -0.272943 2.26513</acceleration>
          <wrench>-8.72104 0.707704 137.439 0 -0 0</wrench>
        </link>
        <link name='rear_left_steering_link'>
          <pose frame=''>-0.50936 0.227958 0.260005 0.000122 -0.001223 0.082495</pose>
          <velocity>-0.001312 0.002235 -0.003772 -0.016223 -0.003029 -0.020439</velocity>
          <acceleration>-1.68503 8.80383 -9.11364 -0.808803 1.33463 -1.79096</acceleration>
          <wrench>-9.62894 50.3085 -52.0789 0 -0 0</wrench>
        </link>
        <link name='rear_left_wheel_link'>
          <pose frame=''>-0.509167 0.227963 0.100005 8e-05 -0.29838 0.082468</pose>
          <velocity>-0.000142 -0.001198 -0.003776 -0.017556 -0.004523 -0.01705</velocity>
          <acceleration>0.245584 1.13756 -9.16037 2.34717 -0.737304 -1.37273</acceleration>
          <wrench>0.906342 4.19822 -33.8068 0 -0 0</wrench>
        </link>
        <link name='rear_right_steering_link'>
          <pose frame=''>-0.46033 -0.365059 0.260009 -5.8e-05 -0.001197 0.082503</pose>
          <velocity>-0.001146 0.002169 0.003377 -0.017845 -0.008164 0.023124</velocity>
          <acceleration>-3.93431 8.50209 6.98974 -0.338384 -1.39789 -1.92024</acceleration>
          <wrench>-22.4822 48.5843 39.9421 0 -0 0</wrench>
        </link>
        <link name='rear_right_wheel_link'>
          <pose frame=''>-0.460136 -0.365052 0.100011 0.000127 0.190831 0.082604</pose>
          <velocity>0.00042 -0.001423 0.003713 0.014195 0.004354 -0.000942</velocity>
          <acceleration>0.27793 0.552336 7.56129 -2.83885 0.242434 -0.257601</acceleration>
          <wrench>1.02571 2.03842 27.9053 0 -0 0</wrench>
        </link>
      </model>
      <model name='ground_plane'>
        <pose frame=''>0 0 0 0 -0 0</pose>
        <scale>1 1 1</scale>
        <link name='link'>
          <pose frame=''>0 0 0 0 -0 0</pose>
          <velocity>0 0 0 0 -0 0</velocity>
          <acceleration>0 0 0 0 -0 0</acceleration>
          <wrench>0 0 0 0 -0 0</wrench>
        </link>
      </model>
      <light name='sun'>
        <pose frame=''>0 0 10 0 -0 0</pose>
      </light>
    </state>
    <gui fullscreen='0'>
      <camera name='user_camera'>
        <pose frame=''>19.7623 -30.8448 90.2151 0 1.33164 2.73619</pose>
        <view_controller>orbit</view_controller>
        <projection_type>perspective</projection_type>
      </camera>
    </gui>
  </world>
</sdf>
