<?xml version="1.0" ?>
<!-- =================================================================================== -->
<!-- |    This document was autogenerated by xacro from asc.urdf.xacro                 | -->
<!-- |    EDITING THIS FILE BY HAND IS NOT RECOMMENDED                                 | -->
<!-- =================================================================================== -->
<robot name="asc" xmlns:xacro="http://www.ros.org/wiki/xacro">
  <gazebo>
    <plugin filename="libgazebo_ros_control.so" name="gazebo_ros_control">
      <robotNamespace>/</robotNamespace>
      <!--<robotParam>/robot_description</robotParam> -->
      <robotSimType>gazebo_ros_control/DefaultRobotHWSim</robotSimType>
      <legacyModeNS>false</legacyModeNS>
    </plugin>
  </gazebo>
  <link name="base_link"/>
  <joint name="base_link_to_frame" type="fixed">
    <origin rpy="0 0 0" xyz="0 0 0.7"/>
    <parent link="base_link"/>
    <child link="frame_link"/>
  </joint>
  <link name="frame_link">
    <inertial>
      <origin rpy="0 0 0" xyz="-0.191135074026536 0.00147037627768998 -0.144166350352701"/>
      <mass value="54.6845003989778"/>
      <inertia ixx="0.830289508168532" ixy="-7.44170925374484E-07" ixz="-0.168031775231281" iyy="1.89493024064907" iyz="3.6787232173372E-07" izz="1.80540947379668"/>
    </inertial>
    <visual>
      <origin rpy="0 0 0" xyz="0 0 0"/>
      <geometry>
        <mesh filename="package://asc_urdf/meshes/base_link.STL"/>
      </geometry>
      <material name="">
        <color rgba="0.866666666666667 0.866666666666667 0.890196078431372 1"/>
      </material>
    </visual>
  </link>
  <link name="front_right_steering_link">
    <inertial>
      <origin rpy="0 0 0" xyz="0.0 0.0 0.0"/>
      <mass value="0.38"/>
      <inertia ixx="0.00107634033140466" ixy="1.51573650824965E-05" ixz="-6.94838293881106E-05" iyy="0.000914613440717638" iyz="0.000195407309247701" izz="0.000234021785961031"/>
    </inertial>
    <!--       <visual>
        <origin
          xyz="0 0 0"
          rpy="0 0 0" />
        <geometry>
          <mesh
            filename="package://asc_urdf/meshes/${wheel_prefix}_steering_link.STL"
            />
        </geometry>
        <material
          name="">
          <color
            rgba="0.792156862745098 0.819607843137255 0.933333333333333 1" />
        </material>
      </visual> -->
    <!--       <collision>
        <origin
          xyz="0 0 0"
          rpy="0 0 0" />
        <geometry>
          <mesh
            filename="package://asc_urdf/meshes/${wheel_prefix}_steering_link.STL" />
        </geometry>
      </collision> -->
  </link>
  <link name="front_right_wheel_link">
    <inertial>
      <origin rpy="0 0 0" xyz="-1.78085064877393 -0.596628586488151 1.14528514474377"/>
      <mass value="368.982800568637"/>
      <inertia ixx="133.019788003658" ixy="-43.9800933039268" ixz="50.7007125568813" iyy="317.318424128749" iyz="25.9183879205888" izz="292.361193071731"/>
    </inertial>
    <visual>
      <origin rpy="1.57 0 0" xyz="0 0 0"/>
      <geometry>
        <cylinder length="0.032" radius="0.1"/>
      </geometry>
      <material name="">
        <color rgba="1 1 1 1"/>
      </material>
    </visual>
    <collision>
      <origin rpy="1.57 0 0" xyz="0 0 0"/>
      <geometry>
        <cylinder length="0.032" radius="0.1"/>
      </geometry>
    </collision>
  </link>
  <joint name="front_right_wheel_joint" type="continuous">
    <origin rpy="0.13981 0.28531 1.6105" xyz="0.024 0.023741 -0.18704"/>
    <parent link="front_right_steering_link"/>
    <child link="front_right_wheel_link"/>
    <axis xyz="5.3677E-05 1 0.00055924"/>
  </joint>
  <transmission name="front_right_wheel_joint_tran">
    <type>transmission_interface/SimpleTransmission</type>
    <joint name="front_right_wheel_joint">
      <hardwareInterface>hardware_interface/VelocityJointInterface</hardwareInterface>
    </joint>
    <actuator name="front_right_wheel_joint_motor">
      <hardwareInterface>hardware_interface/VelocityJointInterface</hardwareInterface>
      <mechanicalReduction>1</mechanicalReduction>
    </actuator>
  </transmission>
  <transmission name="front_right_steering_tran">
    <type>transmission_interface/SimpleTransmission</type>
    <joint name="front_right_steering_joint">
      <hardwareInterface>hardware_interface/PositionJointInterface</hardwareInterface>
    </joint>
    <actuator name="front_right_steering_motor">
      <hardwareInterface>hardware_interface/PositionJointInterface</hardwareInterface>
      <mechanicalReduction>1</mechanicalReduction>
    </actuator>
  </transmission>
  <!-- Add specfic parts for forward wheels-->
  <joint name="front_right_steering_joint" type="revolute">
    <origin rpy="0.29046 -0.12882 -1.6092" xyz="0.35635 -0.23074 0.27672"/>
    <parent link="frame_link"/>
    <child link="front_right_steering_link"/>
    <axis xyz="0 0 -1"/>
    <limit effort="0" lower="-0.3" upper="0.3" velocity="0"/>
  </joint>
  <link name="front_left_steering_link">
    <inertial>
      <origin rpy="0 0 0" xyz="0.0 0.0 0.0"/>
      <mass value="0.38"/>
      <inertia ixx="0.00107634033140466" ixy="1.51573650824965E-05" ixz="-6.94838293881106E-05" iyy="0.000914613440717638" iyz="0.000195407309247701" izz="0.000234021785961031"/>
    </inertial>
    <!--       <visual>
        <origin
          xyz="0 0 0"
          rpy="0 0 0" />
        <geometry>
          <mesh
            filename="package://asc_urdf/meshes/${wheel_prefix}_steering_link.STL"
            />
        </geometry>
        <material
          name="">
          <color
            rgba="0.792156862745098 0.819607843137255 0.933333333333333 1" />
        </material>
      </visual> -->
    <!--       <collision>
        <origin
          xyz="0 0 0"
          rpy="0 0 0" />
        <geometry>
          <mesh
            filename="package://asc_urdf/meshes/${wheel_prefix}_steering_link.STL" />
        </geometry>
      </collision> -->
  </link>
  <link name="front_left_wheel_link">
    <inertial>
      <origin rpy="0 0 0" xyz="-1.78085064877393 -0.596628586488151 1.14528514474377"/>
      <mass value="368.982800568637"/>
      <inertia ixx="133.019788003658" ixy="-43.9800933039268" ixz="50.7007125568813" iyy="317.318424128749" iyz="25.9183879205888" izz="292.361193071731"/>
    </inertial>
    <visual>
      <origin rpy="1.57 0 0" xyz="0 0 0"/>
      <geometry>
        <cylinder length="0.032" radius="0.1"/>
      </geometry>
      <material name="">
        <color rgba="1 1 1 1"/>
      </material>
    </visual>
    <collision>
      <origin rpy="1.57 0 0" xyz="0 0 0"/>
      <geometry>
        <cylinder length="0.032" radius="0.1"/>
      </geometry>
    </collision>
  </link>
  <joint name="front_left_wheel_joint" type="continuous">
    <origin rpy="1.5963E-05 0.28907 1.5707" xyz="-0.05 0.023546 -0.17951"/>
    <parent link="front_left_steering_link"/>
    <child link="front_left_wheel_link"/>
    <axis xyz="5.3677E-05 -1 0.00055924"/>
  </joint>
  <transmission name="front_left_wheel_joint_tran">
    <type>transmission_interface/SimpleTransmission</type>
    <joint name="front_left_wheel_joint">
      <hardwareInterface>hardware_interface/VelocityJointInterface</hardwareInterface>
    </joint>
    <actuator name="front_left_wheel_joint_motor">
      <hardwareInterface>hardware_interface/VelocityJointInterface</hardwareInterface>
      <mechanicalReduction>1</mechanicalReduction>
    </actuator>
  </transmission>
  <transmission name="front_left_steering_tran">
    <type>transmission_interface/SimpleTransmission</type>
    <joint name="front_left_steering_joint">
      <hardwareInterface>hardware_interface/PositionJointInterface</hardwareInterface>
    </joint>
    <actuator name="front_left_steering_motor">
      <hardwareInterface>hardware_interface/PositionJointInterface</hardwareInterface>
      <mechanicalReduction>1</mechanicalReduction>
    </actuator>
  </transmission>
  <!-- Add specfic parts for forward wheels-->
  <joint name="front_left_steering_joint" type="revolute">
    <origin rpy="0.28907 0.00024223 -1.5707" xyz="0.35635 0.22966 0.27672"/>
    <parent link="frame_link"/>
    <child link="front_left_steering_link"/>
    <axis xyz="0 0 -1"/>
    <limit effort="0" lower="-0.3" upper="0.3" velocity="0"/>
  </joint>
  <link name="rear_right_steering_link">
    <inertial>
      <origin rpy="0 0 0" xyz="0.0 0.0 0.0"/>
      <mass value="0.38"/>
      <inertia ixx="0.00107634033140466" ixy="1.51573650824965E-05" ixz="-6.94838293881106E-05" iyy="0.000914613440717638" iyz="0.000195407309247701" izz="0.000234021785961031"/>
    </inertial>
    <!--       <visual>
        <origin
          xyz="0 0 0"
          rpy="0 0 0" />
        <geometry>
          <mesh
            filename="package://asc_urdf/meshes/${wheel_prefix}_steering_link.STL"
            />
        </geometry>
        <material
          name="">
          <color
            rgba="0.792156862745098 0.819607843137255 0.933333333333333 1" />
        </material>
      </visual> -->
    <!--       <collision>
        <origin
          xyz="0 0 0"
          rpy="0 0 0" />
        <geometry>
          <mesh
            filename="package://asc_urdf/meshes/${wheel_prefix}_steering_link.STL" />
        </geometry>
      </collision> -->
  </link>
  <link name="rear_right_wheel_link">
    <inertial>
      <origin rpy="0 0 0" xyz="-1.78085064877393 -0.596628586488151 1.14528514474377"/>
      <mass value="368.982800568637"/>
      <inertia ixx="133.019788003658" ixy="-43.9800933039268" ixz="50.7007125568813" iyy="317.318424128749" iyz="25.9183879205888" izz="292.361193071731"/>
    </inertial>
    <visual>
      <origin rpy="1.57 0 0" xyz="0 0 0"/>
      <geometry>
        <cylinder length="0.032" radius="0.1"/>
      </geometry>
      <material name="">
        <color rgba="1 1 1 1"/>
      </material>
    </visual>
    <collision>
      <origin rpy="1.57 0 0" xyz="0 0 0"/>
      <geometry>
        <cylinder length="0.032" radius="0.1"/>
      </geometry>
    </collision>
  </link>
  <joint name="rear_right_wheel_joint" type="continuous">
    <origin rpy="0 0 0" xyz="0.0 0.0 -0.16"/>
    <parent link="rear_right_steering_link"/>
    <child link="rear_right_wheel_link"/>
    <axis xyz="0 -1 0"/>
  </joint>
  <transmission name="rear_right_wheel_joint_tran">
    <type>transmission_interface/SimpleTransmission</type>
    <joint name="rear_right_wheel_joint">
      <hardwareInterface>hardware_interface/VelocityJointInterface</hardwareInterface>
    </joint>
    <actuator name="rear_right_wheel_joint_motor">
      <hardwareInterface>hardware_interface/VelocityJointInterface</hardwareInterface>
      <mechanicalReduction>1</mechanicalReduction>
    </actuator>
  </transmission>
  <transmission name="rear_right_steering_tran">
    <type>transmission_interface/SimpleTransmission</type>
    <joint name="rear_right_steering_joint">
      <hardwareInterface>hardware_interface/PositionJointInterface</hardwareInterface>
    </joint>
    <actuator name="rear_right_steering_motor">
      <hardwareInterface>hardware_interface/PositionJointInterface</hardwareInterface>
      <mechanicalReduction>1</mechanicalReduction>
    </actuator>
  </transmission>
  <!-- Add specfic parts for forward wheels-->
  <joint name="rear_right_steering_joint" type="revolute">
    <origin rpy="0.0 0.0 0.0" xyz="-0.48012 -0.29752 0.27"/>
    <parent link="frame_link"/>
    <child link="rear_right_steering_link"/>
    <axis xyz="0 0 -1"/>
    <limit effort="0" lower="0.0" upper="0.0" velocity="0"/>
  </joint>
  <link name="rear_left_steering_link">
    <inertial>
      <origin rpy="0 0 0" xyz="0.0 0.0 0.0"/>
      <mass value="0.38"/>
      <inertia ixx="0.00107634033140466" ixy="1.51573650824965E-05" ixz="-6.94838293881106E-05" iyy="0.000914613440717638" iyz="0.000195407309247701" izz="0.000234021785961031"/>
    </inertial>
    <!--       <visual>
        <origin
          xyz="0 0 0"
          rpy="0 0 0" />
        <geometry>
          <mesh
            filename="package://asc_urdf/meshes/${wheel_prefix}_steering_link.STL"
            />
        </geometry>
        <material
          name="">
          <color
            rgba="0.792156862745098 0.819607843137255 0.933333333333333 1" />
        </material>
      </visual> -->
    <!--       <collision>
        <origin
          xyz="0 0 0"
          rpy="0 0 0" />
        <geometry>
          <mesh
            filename="package://asc_urdf/meshes/${wheel_prefix}_steering_link.STL" />
        </geometry>
      </collision> -->
  </link>
  <link name="rear_left_wheel_link">
    <inertial>
      <origin rpy="0 0 0" xyz="-1.78085064877393 -0.596628586488151 1.14528514474377"/>
      <mass value="368.982800568637"/>
      <inertia ixx="133.019788003658" ixy="-43.9800933039268" ixz="50.7007125568813" iyy="317.318424128749" iyz="25.9183879205888" izz="292.361193071731"/>
    </inertial>
    <visual>
      <origin rpy="1.57 0 0" xyz="0 0 0"/>
      <geometry>
        <cylinder length="0.032" radius="0.1"/>
      </geometry>
      <material name="">
        <color rgba="1 1 1 1"/>
      </material>
    </visual>
    <collision>
      <origin rpy="1.57 0 0" xyz="0 0 0"/>
      <geometry>
        <cylinder length="0.032" radius="0.1"/>
      </geometry>
    </collision>
  </link>
  <joint name="rear_left_wheel_joint" type="continuous">
    <origin rpy="0 0 0" xyz="0.0 0.0 -0.16"/>
    <parent link="rear_left_steering_link"/>
    <child link="rear_left_wheel_link"/>
    <axis xyz="0 1 0"/>
  </joint>
  <transmission name="rear_left_wheel_joint_tran">
    <type>transmission_interface/SimpleTransmission</type>
    <joint name="rear_left_wheel_joint">
      <hardwareInterface>hardware_interface/VelocityJointInterface</hardwareInterface>
    </joint>
    <actuator name="rear_left_wheel_joint_motor">
      <hardwareInterface>hardware_interface/VelocityJointInterface</hardwareInterface>
      <mechanicalReduction>1</mechanicalReduction>
    </actuator>
  </transmission>
  <transmission name="rear_left_steering_tran">
    <type>transmission_interface/SimpleTransmission</type>
    <joint name="rear_left_steering_joint">
      <hardwareInterface>hardware_interface/PositionJointInterface</hardwareInterface>
    </joint>
    <actuator name="rear_left_steering_motor">
      <hardwareInterface>hardware_interface/PositionJointInterface</hardwareInterface>
      <mechanicalReduction>1</mechanicalReduction>
    </actuator>
  </transmission>
  <!-- Add specfic parts for forward wheels-->
  <joint name="rear_left_steering_joint" type="revolute">
    <origin rpy="0.0 0.0 0.0" xyz="-0.48012 0.29752 0.27"/>
    <parent link="frame_link"/>
    <child link="rear_left_steering_link"/>
    <axis xyz="0 0 -1"/>
    <limit effort="0" lower="0.0" upper="0.0" velocity="0"/>
  </joint>
</robot>
